Traceback (most recent call last):
  File "paths_constraints_main.py", line 5, in <module>
  File "/home/ittay.al/venv/pproc/lib/python3.7/site-packages/angr/__init__.py", line 22, in <module>
  File "/home/ittay.al/venv/pproc/lib/python3.7/site-packages/angr/utils/__init__.py", line 3, in <module>
  File "/home/ittay.al/venv/pproc/lib/python3.7/site-packages/angr/utils/graph.py", line 5, in <module>
  File "/home/ittay.al/venv/pproc/lib/python3.7/site-packages/networkx/__init__.py", line 72, in <module>
  File "/home/ittay.al/venv/pproc/lib/python3.7/site-packages/networkx/generators/__init__.py", line 8, in <module>
  File "/home/ittay.al/venv/pproc/lib/python3.7/site-packages/networkx/generators/community.py", line 3, in <module>
ImportError: /home/ittay.al/miniconda3/envs/tf1/lib/python3.7/lib-dynload/math.cpython-37m-x86_64-linux-gnu.so: failed to map segment from shared object
